<sdf version='1.10'>
  <world name='empty'>
    <physics name='1ms' type='ignored'>
      <max_step_size>0.001</max_step_size>
      <real_time_factor>1</real_time_factor>
      <real_time_update_rate>1000</real_time_update_rate>
    </physics>
    <plugin name='gz::sim::systems::Physics' filename='gz-sim-physics-system'/>
    <plugin name='gz::sim::systems::UserCommands' filename='gz-sim-user-commands-system'/>
    <plugin name='gz::sim::systems::SceneBroadcaster' filename='gz-sim-scene-broadcaster-system'/>
    <plugin name='gz::sim::systems::Contact' filename='gz-sim-contact-system'/>
    <plugin name='gz::sim::systems::ParticleEmitter' filename='gz-sim-particle-emitter-system'/>
    <gravity>0 0 -9.8000000000000007</gravity>
    <magnetic_field>5.5644999999999998e-06 2.2875799999999999e-05 -4.2388400000000002e-05</magnetic_field>
    <atmosphere type='adiabatic'/>
    <scene>
      <ambient>0.400000006 0.400000006 0.400000006 1</ambient>
      <background>0.699999988 0.699999988 0.699999988 1</background>
      <shadows>true</shadows>
    </scene>
    <model name='ground_plane'>
      <static>true</static>
      <link name='link'>
        <collision name='collision'>
          <geometry>
            <plane>
              <normal>0 0 1</normal>
              <size>100 100</size>
            </plane>
          </geometry>
          <surface>
            <friction>
              <ode/>
            </friction>
            <bounce/>
            <contact/>
          </surface>
        </collision>
        <visual name='visual'>
          <geometry>
            <plane>
              <normal>0 0 1</normal>
              <size>100 100</size>
            </plane>
          </geometry>
          <material>
            <ambient>0.800000012 0.800000012 0.800000012 1</ambient>
            <diffuse>0.800000012 0.800000012 0.800000012 1</diffuse>
            <specular>0.800000012 0.800000012 0.800000012 1</specular>
          </material>
        </visual>
        <pose>0 0 0 0 0 0</pose>
        <inertial>
          <pose>0 0 0 0 0 0</pose>
          <mass>1</mass>
          <inertia>
            <ixx>1</ixx>
            <ixy>0</ixy>
            <ixz>0</ixz>
            <iyy>1</iyy>
            <iyz>0</iyz>
            <izz>1</izz>
          </inertia>
        </inertial>
        <enable_wind>false</enable_wind>
      </link>
      <pose>4 0 0 0 0 0</pose>
      <self_collide>false</self_collide>
    </model>
    <model name='puzzlebot1' canonical_link='chassis'>
      <pose>-0.89400000000000002 0.90600000000000003 0 0 0 0</pose>
      <link name='chassis'>
        <pose>0 0 0.050000000000000003 0 0 0</pose>
        <inertial>
          <mass>0.80000000000000004</mass>
          <pose>0 0 0 0 0 0</pose>
          <inertia>
            <ixx>0.070000000000000007</ixx>
            <iyy>0.080000000000000002</iyy>
            <izz>0.10000000000000001</izz>
            <ixy>0</ixy>
            <ixz>0</ixz>
            <iyz>0</iyz>
          </inertia>
        </inertial>
        <visual name='visual'>
          <geometry>
            <mesh>
              <uri>file:///root/octavo_ws/src/TE3003B/puzzlebot_sim/models/puzzlebot_lidar/meshes/chassis1.dae</uri>
            </mesh>
          </geometry>
        </visual>
        <collision name='collision'>
          <pose>0 0 0 0 0 0</pose>
          <geometry>
            <box>
              <size>0.20000000000000001 0.16 0.045999999999999999</size>
            </box>
          </geometry>
          <surface>
            <friction>
              <ode/>
            </friction>
            <bounce/>
            <contact/>
          </surface>
        </collision>
        <sensor name='imager' type='camera'>
          <pose>0 0 0 0 0 0</pose>
          <topic>camera_image</topic>
          <update_rate>30</update_rate>
          <enable_metrics>false</enable_metrics>
          <camera name='__default__'>
            <pose>0 0 0 0 0 0</pose>
            <horizontal_fov>0.62</horizontal_fov>
            <image>
              <width>1280</width>
              <height>960</height>
              <format>RGB_INT8</format>
              <anti_aliasing>4</anti_aliasing>
            </image>
            <camera_info_topic>camera_info</camera_info_topic>
            <trigger_topic></trigger_topic>
            <triggered>false</triggered>
            <clip>
              <near>0.10000000000000001</near>
              <far>3000</far>
            </clip>
            <save enabled='false'>
              <path>__default__</path>
            </save>
            <visibility_mask>4294967295</visibility_mask>
            <noise>
              <type>none</type>
              <mean>0</mean>
              <stddev>0</stddev>
            </noise>
            <distortion>
              <k1>0</k1>
              <k2>0</k2>
              <k3>0</k3>
              <p1>0</p1>
              <p2>0</p2>
              <center>0.5 0.5</center>
            </distortion>
            <lens>
              <type>stereographic</type>
              <scale_to_hfov>true</scale_to_hfov>
              <cutoff_angle>1.5707963267948966</cutoff_angle>
              <env_texture_size>256</env_texture_size>
            </lens>
            <optical_frame_id></optical_frame_id>
          </camera>
        </sensor>
        <sensor name='gpu_lidar' type='gpu_lidar'>
          <pose>0 0 0.059999999999999998 0 0 1.5700000000000001</pose>
          <topic>lidar</topic>
          <update_rate>10</update_rate>
          <enable_metrics>false</enable_metrics>
          <lidar>
            <scan>
              <horizontal>
                <samples>360</samples>
                <resolution>1</resolution>
                <min_angle>-3.1400000000000001</min_angle>
                <max_angle>3.1400000000000001</max_angle>
              </horizontal>
              <vertical>
                <samples>1</samples>
                <min_angle>0</min_angle>
                <max_angle>0</max_angle>
                <resolution>1</resolution>
              </vertical>
            </scan>
            <range>
              <min>0.20000000000000001</min>
              <max>6</max>
              <resolution>0.050000000000000003</resolution>
            </range>
            <noise>
              <type>gaussian</type>
              <mean>0</mean>
              <stddev>0.01</stddev>
            </noise>
            <visibility_mask>4294967295</visibility_mask>
          </lidar>
        </sensor>
        <enable_wind>false</enable_wind>
      </link>
      <link name='right_wheel'>
        <pose>-8.8817841970012523e-16 -0.095000000000000084 0.05000000000000001 4.9068372439163194e-17 -5.2958952582718031e-13 3.1415000000000002</pose>
        <inertial>
          <mass>0.050000000000000003</mass>
          <inertia>
            <ixx>5.1e-05</ixx>
            <iyy>5.1e-05</iyy>
            <izz>9.0000000000000006e-05</izz>
            <ixy>0</ixy>
            <ixz>0</ixz>
            <iyz>0</iyz>
          </inertia>
          <pose>0 0 0 0 0 0</pose>
        </inertial>
        <visual name='visual'>
          <geometry>
            <mesh>
              <uri>file:///root/octavo_ws/src/TE3003B/puzzlebot_sim/models/puzzlebot_lidar/meshes/wheel.dae</uri>
            </mesh>
          </geometry>
        </visual>
        <collision name='collision'>
          <pose>0 0 0 1.5707 0 0</pose>
          <geometry>
            <cylinder>
              <radius>0.050000000000000003</radius>
              <length>0.0050000000000000001</length>
            </cylinder>
          </geometry>
          <surface>
            <friction>
              <ode>
                <mu>1</mu>
                <mu2>20000.200000000001</mu2>
              </ode>
            </friction>
            <bounce/>
            <contact/>
          </surface>
        </collision>
        <enable_wind>false</enable_wind>
      </link>
      <link name='left_wheel'>
        <pose>-8.8817841970012523e-16 0.094999999999999862 0.05000000000000001 -1.0096114592985847e-28 2.1802287131564425e-15 2.2449120913163134e-33</pose>
        <inertial>
          <mass>0.050000000000000003</mass>
          <inertia>
            <ixx>5.1e-05</ixx>
            <iyy>5.1e-05</iyy>
            <izz>9.0000000000000006e-05</izz>
            <ixy>0</ixy>
            <ixz>0</ixz>
            <iyz>0</iyz>
          </inertia>
          <pose>0 0 0 0 0 0</pose>
        </inertial>
        <visual name='visual'>
          <geometry>
            <mesh>
              <uri>file:///root/octavo_ws/src/TE3003B/puzzlebot_sim/models/puzzlebot_lidar/meshes/wheel.dae</uri>
            </mesh>
          </geometry>
        </visual>
        <collision name='collision'>
          <pose>0 0 0 1.5707 0 0</pose>
          <geometry>
            <cylinder>
              <radius>0.050000000000000003</radius>
              <length>0.0050000000000000001</length>
            </cylinder>
          </geometry>
          <surface>
            <friction>
              <ode>
                <mu>1</mu>
                <mu2>20000.200000000001</mu2>
              </ode>
            </friction>
            <bounce/>
            <contact/>
          </surface>
        </collision>
        <enable_wind>false</enable_wind>
      </link>
      <frame name='caster_frame' attached_to='chassis'>
        <pose>-0.14499999999999999 0 -0.043999999999999997 0 0 0</pose>
      </frame>
      <link name='caster'>
        <pose>-0.14500000000000057 0 0.0060000000000000123 3.4723978635961569e-12 1.721069681954553e-07 -1.3524914280157635e-13</pose>
        <inertial>
          <mass>0.01</mass>
          <inertia>
            <ixx>5.1e-05</ixx>
            <iyy>5.1e-05</iyy>
            <izz>9.0000000000000006e-05</izz>
            <ixy>0</ixy>
            <ixz>0</ixz>
            <iyz>0</iyz>
          </inertia>
          <pose>0 0 0 0 0 0</pose>
        </inertial>
        <visual name='visual'>
          <geometry>
            <sphere>
              <radius>0.0060000000000000001</radius>
            </sphere>
          </geometry>
          <material>
            <ambient>0 1 0 1</ambient>
            <diffuse>0 1 0 1</diffuse>
            <specular>0 1 0 1</specular>
          </material>
        </visual>
        <collision name='collision'>
          <geometry>
            <sphere>
              <radius>0.0060000000000000001</radius>
            </sphere>
          </geometry>
          <surface>
            <friction>
              <ode/>
            </friction>
            <bounce/>
            <contact/>
          </surface>
        </collision>
        <enable_wind>false</enable_wind>
      </link>
      <joint name='left_wheel_joint' type='revolute'>
        <pose>1.9721522630525295e-31 0 0 0 1.1332444863110088e-61 0</pose>
        <parent>chassis</parent>
        <child>left_wheel</child>
        <axis>
          <xyz>0 1 0</xyz>
          <limit>
            <lower>-1.7976900000000001e+308</lower>
            <upper>1.7976900000000001e+308</upper>
            <effort>1</effort>
            <velocity>inf</velocity>
            <stiffness>100000000</stiffness>
            <dissipation>1</dissipation>
          </limit>
          <dynamics>
            <spring_reference>0</spring_reference>
            <spring_stiffness>0</spring_stiffness>
            <damping>0</damping>
            <friction>0.10000000000000001</friction>
          </dynamics>
        </axis>
      </joint>
      <joint name='right_wheel_joint' type='revolute'>
        <pose>0 -2.7755575615628914e-17 2.7755575615628914e-17 0 0 0</pose>
        <parent>chassis</parent>
        <child>right_wheel</child>
        <axis>
          <xyz>9.2653589660490244e-05 -0.99999999570765619 0</xyz>
          <limit>
            <lower>-1.7976900000000001e+308</lower>
            <upper>1.7976900000000001e+308</upper>
            <effort>1</effort>
            <velocity>inf</velocity>
            <stiffness>100000000</stiffness>
            <dissipation>1</dissipation>
          </limit>
          <dynamics>
            <spring_reference>0</spring_reference>
            <spring_stiffness>0</spring_stiffness>
            <damping>0</damping>
            <friction>0.10000000000000001</friction>
          </dynamics>
        </axis>
      </joint>
      <joint name='caster_wheel' type='ball'>
        <parent>chassis</parent>
        <child>caster</child>
        <pose>0 -2.1693674893577825e-30 8.6736173798840355e-19 0 2.3481993684272088e-25 0</pose>
      </joint>
      <plugin name='gz::sim::systems::DiffDrive' filename='libgz-sim8-diff-drive-system.so'>
        <left_joint>left_wheel_joint</left_joint>
        <right_joint>right_wheel_joint</right_joint>
        <wheel_separation>0.19</wheel_separation>
        <wheel_radius>0.05</wheel_radius>
        <topic>cmd_vel</topic>
        <odom_topic>/odom</odom_topic>
      </plugin>
      <frame name='lidar_frame' attached_to='chassis'>
        <pose>0 0 0.059999999999999998 0 0 0</pose>
      </frame>
      <plugin name='gz::sim::systems::Sensors' filename='gz-sim-sensors-system'>
        <render_engine>ogre2</render_engine>
      </plugin>
      <pose>0 0 0 0 0 0</pose>
      <static>false</static>
      <self_collide>false</self_collide>
    </model>
    <include>
      <uri>file:///root/octavo_ws/src/TE3003B/puzzlebot_sim/models/Aruco13</uri>
      <name>Aruco13</name>
      <pose>0.55500000000000005 0.76100000000000001 0.055 0 0 3.1400000000000001</pose>
    </include>
    <include>
      <uri>file:///root/octavo_ws/src/TE3003B/puzzlebot_sim/models/Aruco11</uri>
      <name>Aruco11</name>
      <pose>-1.1899999999999999 -0.074999999999999997 0.055 0 0 0</pose>
    </include>
    <model name='box'>
      <pose>1.3149999999999999 0 0.14999999999999999 0 0 0</pose>
      <link name='box_link'>
        <inertial>
          <inertia>
            <ixx>0.16666</ixx>
            <ixy>0</ixy>
            <ixz>0</ixz>
            <iyy>0.16666</iyy>
            <iyz>0</iyz>
            <izz>0.16666</izz>
          </inertia>
          <mass>1</mass>
          <pose>0 0 0 0 0 0</pose>
        </inertial>
        <collision name='box_collision'>
          <geometry>
            <box>
              <size>0.25 2.8799999999999999 0.29999999999999999</size>
            </box>
          </geometry>
          <surface>
            <friction>
              <ode/>
            </friction>
            <bounce/>
            <contact/>
          </surface>
        </collision>
        <visual name='box_visual'>
          <geometry>
            <box>
              <size>0.25 2.8799999999999999 0.29999999999999999</size>
            </box>
          </geometry>
          <material>
            <ambient>0.300000012 0.300000012 0.300000012 1</ambient>
            <diffuse>0.699999988 0.699999988 0.699999988 1</diffuse>
            <specular>1 1 1 1</specular>
          </material>
        </visual>
        <pose>0 0 0 0 0 0</pose>
        <enable_wind>false</enable_wind>
      </link>
      <static>false</static>
      <self_collide>false</self_collide>
    </model>
    <model name='box_0'>
      <pose>0 1.3149999999999999 0.14999999999999999 0 0 0</pose>
      <link name='box_link'>
        <inertial>
          <inertia>
            <ixx>0.16666</ixx>
            <ixy>0</ixy>
            <ixz>0</ixz>
            <iyy>0.16666</iyy>
            <iyz>0</iyz>
            <izz>0.16666</izz>
          </inertia>
          <mass>1</mass>
          <pose>0 0 0 0 0 0</pose>
        </inertial>
        <collision name='box_collision'>
          <geometry>
            <box>
              <size>2.3799999999999999 0.25 0.29999999999999999</size>
            </box>
          </geometry>
          <surface>
            <friction>
              <ode/>
            </friction>
            <bounce/>
            <contact/>
          </surface>
        </collision>
        <visual name='box_visual'>
          <geometry>
            <box>
              <size>2.3799999999999999 0.25 0.29999999999999999</size>
            </box>
          </geometry>
          <material>
            <ambient>0.300000012 0.300000012 0.300000012 1</ambient>
            <diffuse>0.699999988 0.699999988 0.699999988 1</diffuse>
            <specular>1 1 1 1</specular>
          </material>
        </visual>
        <pose>0 0 0 0 0 0</pose>
        <enable_wind>false</enable_wind>
      </link>
      <static>false</static>
      <self_collide>false</self_collide>
    </model>
    <model name='box_1'>
      <pose>0 -1.3149999999999999 0.14999999999999999 0 0 0</pose>
      <link name='box_link'>
        <inertial>
          <inertia>
            <ixx>0.16666</ixx>
            <ixy>0</ixy>
            <ixz>0</ixz>
            <iyy>0.16666</iyy>
            <iyz>0</iyz>
            <izz>0.16666</izz>
          </inertia>
          <mass>1</mass>
          <pose>0 0 0 0 0 0</pose>
        </inertial>
        <collision name='box_collision'>
          <geometry>
            <box>
              <size>2.3799999999999999 0.25 0.29999999999999999</size>
            </box>
          </geometry>
          <surface>
            <friction>
              <ode/>
            </friction>
            <bounce/>
            <contact/>
          </surface>
        </collision>
        <visual name='box_visual'>
          <geometry>
            <box>
              <size>2.3799999999999999 0.25 0.29999999999999999</size>
            </box>
          </geometry>
          <material>
            <ambient>0.300000012 0.300000012 0.300000012 1</ambient>
            <diffuse>0.699999988 0.699999988 0.699999988 1</diffuse>
            <specular>1 1 1 1</specular>
          </material>
        </visual>
        <pose>0 0 0 0 0 0</pose>
        <enable_wind>false</enable_wind>
      </link>
      <static>false</static>
      <self_collide>false</self_collide>
    </model>
    <model name='box_2'>
      <pose>-1.3149999999999999 0 0.14999999999999999 0 0 0</pose>
      <link name='box_link'>
        <inertial>
          <inertia>
            <ixx>0.16666</ixx>
            <ixy>0</ixy>
            <ixz>0</ixz>
            <iyy>0.16666</iyy>
            <iyz>0</iyz>
            <izz>0.16666</izz>
          </inertia>
          <mass>1</mass>
          <pose>0 0 0 0 0 0</pose>
        </inertial>
        <collision name='box_collision'>
          <geometry>
            <box>
              <size>0.25 2.8799999999999999 0.29999999999999999</size>
            </box>
          </geometry>
          <surface>
            <friction>
              <ode/>
            </friction>
            <bounce/>
            <contact/>
          </surface>
        </collision>
        <visual name='box_visual'>
          <geometry>
            <box>
              <size>0.25 2.8799999999999999 0.29999999999999999</size>
            </box>
          </geometry>
          <material>
            <ambient>0.300000012 0.300000012 0.300000012 1</ambient>
            <diffuse>0.699999988 0.699999988 0.699999988 1</diffuse>
            <specular>1 1 1 1</specular>
          </material>
        </visual>
        <pose>0 0 0 0 0 0</pose>
        <enable_wind>false</enable_wind>
      </link>
      <static>false</static>
      <self_collide>false</self_collide>
    </model>
    <model name='col'>
      <pose>0.875 0.96999999999999997 0.14999999999999999 0 0 0</pose>
      <link name='col_link'>
        <inertial>
          <inertia>
            <ixx>0.16666</ixx>
            <ixy>0</ixy>
            <ixz>0</ixz>
            <iyy>0.16666</iyy>
            <iyz>0</iyz>
            <izz>0.16666</izz>
          </inertia>
          <mass>1</mass>
          <pose>0 0 0 0 0 0</pose>
        </inertial>
        <collision name='col_collision'>
          <geometry>
            <box>
              <size>0.63 0.44 0.29999999999999999</size>
            </box>
          </geometry>
          <surface>
            <friction>
              <ode/>
            </friction>
            <bounce/>
            <contact/>
          </surface>
        </collision>
        <visual name='col_visual'>
          <geometry>
            <box>
              <size>0.63 0.44 0.29999999999999999</size>
            </box>
          </geometry>
          <material>
            <ambient>0.300000012 0.300000012 0.300000012 1</ambient>
            <diffuse>0.699999988 0.699999988 0.699999988 1</diffuse>
            <specular>1 1 1 1</specular>
          </material>
        </visual>
        <pose>0 0 0 0 0 0</pose>
        <enable_wind>false</enable_wind>
      </link>
      <static>false</static>
      <self_collide>false</self_collide>
    </model>
    <model name='obs_0'>
      <pose>0.34999999999999998 -0.625 0.14999999999999999 0 0 0</pose>
      <link name='obs_link'>
        <inertial>
          <inertia>
            <ixx>0.16666</ixx>
            <ixy>0</ixy>
            <ixz>0</ixz>
            <iyy>0.16666</iyy>
            <iyz>0</iyz>
            <izz>0.16666</izz>
          </inertia>
          <mass>1</mass>
          <pose>0 0 0 0 0 0</pose>
        </inertial>
        <collision name='obs_collision'>
          <geometry>
            <box>
              <size>0.5 0.33000000000000002 0.29999999999999999</size>
            </box>
          </geometry>
          <surface>
            <friction>
              <ode/>
            </friction>
            <bounce/>
            <contact/>
          </surface>
        </collision>
        <visual name='obs_visual'>
          <geometry>
            <box>
              <size>0.5 0.33000000000000002 0.29999999999999999</size>
            </box>
          </geometry>
          <material>
            <ambient>0.300000012 0.300000012 0.300000012 1</ambient>
            <diffuse>0.699999988 0.699999988 0.699999988 1</diffuse>
            <specular>1 1 1 1</specular>
          </material>
        </visual>
        <pose>0 0 0 0 0 0</pose>
        <enable_wind>false</enable_wind>
      </link>
      <static>false</static>
      <self_collide>false</self_collide>
    </model>
    <model name='obs_1'>
      <pose>-0.57999999999999996 -0.44 0.14999999999999999 0 0 0</pose>
      <link name='obs_link'>
        <inertial>
          <inertia>
            <ixx>0.16666</ixx>
            <ixy>0</ixy>
            <ixz>0</ixz>
            <iyy>0.16666</iyy>
            <iyz>0</iyz>
            <izz>0.16666</izz>
          </inertia>
          <mass>1</mass>
          <pose>0 0 0 0 0 0</pose>
        </inertial>
        <collision name='obs_collision'>
          <geometry>
            <box>
              <size>0.33000000000000002 0.5 0.29999999999999999</size>
            </box>
          </geometry>
          <surface>
            <friction>
              <ode/>
            </friction>
            <bounce/>
            <contact/>
          </surface>
        </collision>
        <visual name='obs_visual'>
          <geometry>
            <box>
              <size>0.33000000000000002 0.5 0.29999999999999999</size>
            </box>
          </geometry>
          <material>
            <ambient>0.300000012 0.300000012 0.300000012 1</ambient>
            <diffuse>0.699999988 0.699999988 0.699999988 1</diffuse>
            <specular>1 1 1 1</specular>
          </material>
        </visual>
        <pose>0 0 0 0 0 0</pose>
        <enable_wind>false</enable_wind>
      </link>
      <static>false</static>
      <self_collide>false</self_collide>
    </model>
    <model name='obs_2'>
      <pose>-0.495 0.46500000000000002 0.14999999999999999 0 0 0</pose>
      <link name='obs_link'>
        <inertial>
          <inertia>
            <ixx>0.16666</ixx>
            <ixy>0</ixy>
            <ixz>0</ixz>
            <iyy>0.16666</iyy>
            <iyz>0</iyz>
            <izz>0.16666</izz>
          </inertia>
          <mass>1</mass>
          <pose>0 0 0 0 0 0</pose>
        </inertial>
        <collision name='obs_collision'>
          <geometry>
            <box>
              <size>0.5 0.33000000000000002 0.29999999999999999</size>
            </box>
          </geometry>
          <surface>
            <friction>
              <ode/>
            </friction>
            <bounce/>
            <contact/>
          </surface>
        </collision>
        <visual name='obs_visual'>
          <geometry>
            <box>
              <size>0.5 0.33000000000000002 0.29999999999999999</size>
            </box>
          </geometry>
          <material>
            <ambient>0.300000012 0.300000012 0.300000012 1</ambient>
            <diffuse>0.699999988 0.699999988 0.699999988 1</diffuse>
            <specular>1 1 1 1</specular>
          </material>
        </visual>
        <pose>0 0 0 0 0 0</pose>
        <enable_wind>false</enable_wind>
      </link>
      <static>false</static>
      <self_collide>false</self_collide>
    </model>
    <model name='obs_3'>
      <pose>0.34000000000000002 0.155 0.14999999999999999 0 0 0</pose>
      <link name='obs_link'>
        <inertial>
          <inertia>
            <ixx>0.16666</ixx>
            <ixy>0</ixy>
            <ixz>0</ixz>
            <iyy>0.16666</iyy>
            <iyz>0</iyz>
            <izz>0.16666</izz>
          </inertia>
          <mass>1</mass>
          <pose>0 0 0 0 0 0</pose>
        </inertial>
        <collision name='obs_collision'>
          <geometry>
            <box>
              <size>0.5 0.33000000000000002 0.29999999999999999</size>
            </box>
          </geometry>
          <surface>
            <friction>
              <ode/>
            </friction>
            <bounce/>
            <contact/>
          </surface>
        </collision>
        <visual name='obs_visual'>
          <geometry>
            <box>
              <size>0.5 0.33000000000000002 0.29999999999999999</size>
            </box>
          </geometry>
          <material>
            <ambient>0.300000012 0.300000012 0.300000012 1</ambient>
            <diffuse>0.699999988 0.699999988 0.699999988 1</diffuse>
            <specular>1 1 1 1</specular>
          </material>
        </visual>
        <pose>0 0 0 0 0 0</pose>
        <enable_wind>false</enable_wind>
      </link>
      <static>false</static>
      <self_collide>false</self_collide>
    </model>
    <include>
      <uri>file:///root/octavo_ws/src/TE3003B/puzzlebot_sim/models/Aruco10</uri>
      <name>Aruco10</name>
      <pose>0.85679456401249643 -1.1892763806686828 0.055 0 0 1.57</pose>
    </include>
    <include>
      <uri>file:///root/octavo_ws/src/TE3003B/puzzlebot_sim/models/Aruco8</uri>
      <name>Aruco8</name>
      <pose>0.91363888120453185 0.73996747879192393 0.055 0 0 -1.57</pose>
    </include>
    <include>
      <uri>file:///root/octavo_ws/src/TE3003B/puzzlebot_sim/models/Aruco3</uri>
      <name>Aruco3</name>
      <pose>-0.96919292934399359 -1.1866535968574532 0.055 0 0 1.57</pose>
    </include>
    <include>
      <uri>file:///root/octavo_ws/src/TE3003B/puzzlebot_sim/models/Aruco12</uri>
      <name>Aruco12</name>
      <pose>1.1829422062239214 -0.11577044718381779 0.055 0 0 3.14</pose>
    </include>
    <include>
      <uri>file:///root/octavo_ws/src/TE3003B/puzzlebot_sim/models/Aruco2</uri>
      <name>Aruco2</name>
      <pose>-0.16016609744464755 -1.1910165662134333 0.055 0 0 1.57</pose>
    </include>
    <light name='sun' type='directional'>
      <pose>0 0 10 0 0 0</pose>
      <cast_shadows>true</cast_shadows>
      <intensity>1</intensity>
      <direction>-0.5 0.10000000000000001 -0.90000000000000002</direction>
      <diffuse>0.800000012 0.800000012 0.800000012 1</diffuse>
      <specular>0.200000003 0.200000003 0.200000003 1</specular>
      <attenuation>
        <range>1000</range>
        <linear>0.0099999997764825821</linear>
        <constant>0.89999997615814209</constant>
        <quadratic>0.0010000000474974513</quadratic>
      </attenuation>
      <spot>
        <inner_angle>0</inner_angle>
        <outer_angle>0</outer_angle>
        <falloff>0</falloff>
      </spot>
    </light>
  </world>
</sdf>
